from unittest.mock import patch

import pytest
from pymonetdb import DatabaseError
from pymonetdb import OperationalError
from pymonetdb import ProgrammingError

from exareme2 import AttrDict
from exareme2.worker.exareme2.monetdb.monetdb_facade import _DBExecutionDTO
from exareme2.worker.exareme2.monetdb.monetdb_facade import _execute_and_fetchall
from exareme2.worker.exareme2.monetdb.monetdb_facade import (
    _validate_exception_could_be_recovered,
)
from exareme2.worker.exareme2.monetdb.monetdb_facade import db_execute_and_fetchall
from exareme2.worker.exareme2.monetdb.monetdb_facade import db_execute_query
from exareme2.worker.utils.logger import init_logger
from tests.standalone_tests.conftest import COMMON_IP
from tests.standalone_tests.conftest import MONETDB_LOCALWORKERTMP_NAME
from tests.standalone_tests.conftest import MONETDB_LOCALWORKERTMP_PORT
from tests.standalone_tests.conftest import remove_monetdb_container
from tests.standalone_tests.conftest import restart_monetdb_container


@pytest.fixture(scope="module", autouse=True)
def patch_worker_logger():
    current_task = AttrDict({"request": {"id": "1234"}})

    with patch(
        "exareme2.worker.utils.logger.worker_config",
        AttrDict(
            {
                "log_level": "DEBUG",
                "role": "localworker",
                "identifier": "localworkertmp",
            },
        ),
    ), patch(
        "exareme2.worker.utils.logger.task_loggers",
        {"1234": init_logger("1234")},
    ), patch(
        "exareme2.worker.utils.logger.current_task",
        current_task,
    ):
        yield


@pytest.fixture(autouse=True, scope="module")
def patch_worker_config():
    with patch(
        "exareme2.worker.exareme2.monetdb.monetdb_facade.worker_config",
        AttrDict(
            {
                "monetdb": {
                    "ip": COMMON_IP,
                    "port": MONETDB_LOCALWORKERTMP_PORT,
                    "database": "db",
                    "local_username": "executor",
                    "local_password": "executor",
                    "public_username": "guest",
                    "public_password": "guest",
                },
                "celery": {
                    "tasks_timeout": 5,
                    "run_udf_task_timeout": 120,
                    "worker_concurrency": 1,
                },
            }
        ),
    ):
        yield


@pytest.mark.slow
@pytest.mark.very_slow
def test_execute_and_fetchall_success(
    monetdb_localworkertmp,
):
    db_execution_dto = _DBExecutionDTO(query="select 1;", timeout=1)
    result = _execute_and_fetchall(db_execution_dto=db_execution_dto)
    assert result[0][0] == 1


@pytest.mark.slow
@pytest.mark.very_slow
def test_broken_pipe_error_properly_handled(
    capfd,
    monetdb_localworkertmp,
):
    db_execution_dto = _DBExecutionDTO(query="select 1;", timeout=1)
    result = _execute_and_fetchall(db_execution_dto=db_execution_dto)
    assert result[0][0] == 1
    restart_monetdb_container(MONETDB_LOCALWORKERTMP_NAME)
    db_execution_dto = _DBExecutionDTO(query="select 1;", timeout=1)
    result = _execute_and_fetchall(db_execution_dto=db_execution_dto)
    assert result[0][0] == 1


@pytest.mark.slow
@pytest.mark.very_slow
def test_generic_exception_handled(
    monetdb_localworkertmp,
):
    remove_monetdb_container(MONETDB_LOCALWORKERTMP_NAME)
    db_execution_dto = _DBExecutionDTO(query="select 1;", timeout=1)
    # MonetDB is inaccessible, therefore an OSError is raised.
    with pytest.raises(OSError):
        _execute_and_fetchall(db_execution_dto=db_execution_dto)


@pytest.mark.slow
@pytest.mark.very_slow
# Fix for the task https://team-1617704806227.atlassian.net/browse/MIP-731
def test_connection_error_while_waiting_for_table_to_be_present(monetdb_localworkertmp):
    db_execution_dto = _DBExecutionDTO(
        query="select * from non_existing_table;", timeout=1
    )
    with pytest.raises(OperationalError):
        _execute_and_fetchall(db_execution_dto=db_execution_dto)


def get_exception_cases():
    return [
        pytest.param(
            OSError("OSError"),
            False,
            id="Monetdb is down",
        ),
        pytest.param(
            BrokenPipeError("error"),
            True,
            id="broken pipe occurs on container restart",
        ),
        pytest.param(
            DatabaseError("table not found"),
            True,
            id="generic DatabaseError",
        ),
        pytest.param(
            DatabaseError("python exception"),
            True,
            id="python exception DatabaseError",
        ),
        pytest.param(
            DatabaseError("python exception: ValueError(print stuff)"),
            False,
            id="Algorithms debugging",
        ),
        pytest.param(
            ProgrammingError("ProgrammingError"),
            False,
            id="generic ProgrammingError",
        ),
        pytest.param(
            OperationalError(
                "42000!CREATE TABLE: insufficient privileges for user 'executor' in schema 'guest'"
            ),
            False,
            id="Insufficient privileges Error",
        ),
    ]


@pytest.mark.parametrize(
    "exception,expected",
    get_exception_cases(),
)
def test_validate_exception_is_recoverable(exception: Exception, expected):
    assert _validate_exception_could_be_recovered(exception) == expected


@pytest.mark.slow
@pytest.mark.very_slow
def test_db_execute_use_public_user_parameter(
    monetdb_localworkertmp,
):
    table_name = "local_user_table"

    db_execute_query(query=f"create table {table_name} (col1 int);")

    with pytest.raises(OperationalError, match=r"no such table"):
        db_execute_and_fetchall(
            query=f"select * from {table_name};", use_public_user=True
        )
